Workbook

Sheet Ítems
B2: Licitación: 468573 - MANTENIMIENTO DE DEPOSITOS DE CARGAS AREAS DEL AISP
B4: Grupo 1 - MANTENIMIENTO DE DEPOSITOS DE CARGAS AREAS DEL AISP Contrato Abierto: No, Abastecimiento Simultaneo: No
B5: Ítem | C5: Código Catálogo | D5: Descripción | E5: Atributos | F5: Cantidad | G5: Monto | H5: Precio Unitario (IVA Incluido) | I5: Precio Total | J5: Caracteristicas
B6: 1 | C6: 72141510-001 | D6: Demolicion de contrapiso y piso con aislacion existente. Incluye retiro de escombro | E6: unidad de medida: Metros cuadrados presentación: EVENTO | F6: 900 | G6: - | H6: =+VLOOKUP(B6,COSTEO!B:K,10,0) -> 29000 | I6: =H6*900 -> 26100000 | J6: procedencia: Paraguay nro_certificado_origen_nacional: 202459
B7: 2 | C7: 72131601-004 | D7: Provision de carpeta | E7: unidad de medida: Metros cuadrados presentación: EVENTO | F7: 900 | G7: - | H7: =+VLOOKUP(B7,COSTEO!B:K,10,0) -> 11800 | I7: =H7*900 -> 10620000 | J7: procedencia: Paraguay nro_certificado_origen_nacional:
B8: 3 | C8: 80111613-9999 | D8: Mano de obra de carpeta | E8: unidad de medida: Metros cuadrados presentación: EVENTO | F8: 900 | G8: - | H8: =+VLOOKUP(B8,COSTEO!B:K,10,0) -> 25500 | I8: =H8*900 -> 22950000 | J8: procedencia: Paraguay nro_certificado_origen_nacional: 202459
B9: 4 | C9: 72131601-012 | D9: Provision de membrana liquida y tela bidim para aislacion de losa | E9: unidad de medida: Metros cuadrados presentación: EVENTO | F9: 900 | G9: - | H9: =+VLOOKUP(B9,COSTEO!B:K,10,0) -> 70600 | I9: =H9*900 -> 63540000 | J9: procedencia: Argentina nro_certificado_origen_nacional:
B10: 5 | C10: 80111613-9999 | D10: Mano de obra de membrana liquida y tela bidim para aislacion de losa | E10: unidad de medida: Metros cuadrados presentación: EVENTO | F10: 900 | G10: - | H10: =+VLOOKUP(B10,COSTEO!B:K,10,0) -> 21300 | I10: =H10*900 -> 19170000 | J10: procedencia: Paraguay nro_certificado_origen_nacional: 202459
B11: 6 | C11: 72103002-002 | D11: Remocion de revoque en zonas deterioradas | E11: unidad de medida: Metros cuadrados presentación: EVENTO | F11: 300 | G11: - | H11: =+VLOOKUP(B11,COSTEO!B:K,10,0) -> 10600 | I11: =H11*300 -> 3180000 | J11: procedencia: Paraguay nro_certificado_origen_nacional: 202459
B12: 7 | C12: 72131601-008 | D12: Provision de revoque interior con hidrofugo | E12: unidad de medida: Metros cuadrados presentación: EVENTO | F12: 300 | G12: - | H12: =+VLOOKUP(B12,COSTEO!B:K,10,0) -> 15900 | I12: =H12*300 -> 4770000 | J12: procedencia: Paraguay nro_certificado_origen_nacional:
B13: 8 | C13: 80111613-9999 | D13: Mano de obra - Revoque con hidrófugo | E13: unidad de medida: Metros cuadrados presentación: EVENTO | F13: 300 | G13: - | H13: =+VLOOKUP(B13,COSTEO!B:K,10,0) -> 28100 | I13: =H13*300 -> 8430000 | J13: procedencia: Paraguay nro_certificado_origen_nacional: 202459
B14: 9 | C14: 72131601-012 | D14: Provision de pintura latex para interior con enduido | E14: unidad de medida: Metros cuadrados presentación: EVENTO | F14: 900 | G14: - | H14: =+VLOOKUP(B14,COSTEO!B:K,10,0) -> 15300 | I14: =H14*900 -> 13770000 | J14: procedencia: Brasil nro_certificado_origen_nacional:
B15: 10 | C15: 80111613-9999 | D15: Mano de obra de pintura latex para interior con enduido | E15: unidad de medida: Metros cuadrados presentación: EVENTO | F15: 900 | G15: - | H15: =+VLOOKUP(B15,COSTEO!B:K,10,0) -> 24700 | I15: =H15*900 -> 22230000 | J15: procedencia: Paraguay nro_certificado_origen_nacional: 202459
B16: 11 | C16: 72101603-001 | D16: Mantenimiento de canaleta embutida bajada | E16: unidad de medida: Metro lineal presentación: EVENTO | F16: 50 | G16: - | H16: =+VLOOKUP(B16,COSTEO!B:K,10,0) -> 30000 | I16: =H16*50 -> 1500000 | J16: procedencia: Paraguay nro_certificado_origen_nacional: 202459
B17: 12 | C17: 72101603-9999 | D17: Remocion de canaleta embutida bajada | E17: unidad de medida: Metro lineal presentación: EVENTO | F17: 535 | G17: - | H17: =+VLOOKUP(B17,COSTEO!B:K,10,0) -> 30000 | I17: =H17*535 -> 16050000 | J17: procedencia: Paraguay nro_certificado_origen_nacional: 202460
B18: 13 | C18: 72101603-002 | D18: Provision de Canaleta embutida bajada | E18: unidad de medida: Metro lineal presentación: EVENTO | F18: 535 | G18: - | H18: =+VLOOKUP(B18,COSTEO!B:K,10,0) -> 147200 | I18: =H18*535 -> 78752000 | J18: procedencia: Paraguay nro_certificado_origen_nacional:
B19: 14 | C19: 72101603-9999 | D19: Mano de obra - instalaci撑 de Canaleta embutida + bajada | E19: unidad de medida: Metro lineal presentación: EVENTO | F19: 535 | G19: - | H19: =+VLOOKUP(B19,COSTEO!B:K,10,0) -> 75000 | I19: =H19*535 -> 40125000 | J19: procedencia: Paraguay nro_certificado_origen_nacional: 202459
B20: 15 | C20: 72102304-9995 | D20: Mantenimiento de registro pluviales | E20: unidad de medida: Metro lineal presentación: EVENTO | F20: 270 | G20: - | H20: =+VLOOKUP(B20,COSTEO!B:K,10,0) -> 18000 | I20: =H20*270 -> 4860000 | J20: procedencia: Paraguay nro_certificado_origen_nacional: 202460
B21: 16 | C21: 72103002-002 | D21: Remocion de revoque en zona de humedad | E21: unidad de medida: Metros cuadrados presentación: EVENTO | F21: 300 | G21: - | H21: =+VLOOKUP(B21,COSTEO!B:K,10,0) -> 10300 | I21: =H21*300 -> 3090000 | J21: procedencia: Paraguay nro_certificado_origen_nacional: 202461
B22: 17 | C22: 72131601-008 | D22: Provision de revoque interior con hidrofugo | E22: unidad de medida: Metros cuadrados presentación: EVENTO | F22: 300 | G22: - | H22: =+VLOOKUP(B22,COSTEO!B:K,10,0) -> 15900 | I22: =H22*300 -> 4770000 | J22: procedencia: Paraguay nro_certificado_origen_nacional:
B23: 18 | C23: 72101603-9999 | D23: Mano de obra - Revoque con hidrófugo | E23: unidad de medida: Metros cuadrados presentación: EVENTO | F23: 300 | G23: - | H23: =+VLOOKUP(B23,COSTEO!B:K,10,0) -> 28100 | I23: =H23*300 -> 8430000 | J23: procedencia: Paraguay nro_certificado_origen_nacional: 202459
B24: 19 | C24: 72131601-012 | D24: Provision de pintura latex para interior con enduido | E24: unidad de medida: Metros cuadrados presentación: EVENTO | F24: 400 | G24: - | H24: =+VLOOKUP(B24,COSTEO!B:K,10,0) -> 15300 | I24: =H24*400 -> 6120000 | J24: procedencia: Brasil nro_certificado_origen_nacional:
B25: 20 | C25: 72101603-9999 | D25: Mano de obra de pintura latex para interior con enduido | E25: unidad de medida: Metros cuadrados presentación: EVENTO | F25: 400 | G25: - | H25: =+VLOOKUP(B25,COSTEO!B:K,10,0) -> 20600 | I25: =H25*400 -> 8240000 | J25: procedencia: Paraguay nro_certificado_origen_nacional: 202459
B26: 21 | C26: 72131601-012 | D26: Provision de pintura latex para exterior | E26: unidad de medida: Metros cuadrados presentación: EVENTO | F26: 2000 | G26: - | H26: =+VLOOKUP(B26,COSTEO!B:K,10,0) -> 20400 | I26: =H26*2000 -> 40800000 | J26: procedencia: Brasil nro_certificado_origen_nacional:
B27: 22 | C27: 72101603-9999 | D27: Mano de obra de pintura latex para exterior | E27: unidad de medida: Metros cuadrados presentación: EVENTO | F27: 2000 | G27: - | H27: =+VLOOKUP(B27,COSTEO!B:K,10,0) -> 19800 | I27: =H27*2000 -> 39600000 | J27: procedencia: Paraguay nro_certificado_origen_nacional: 202459
B28: 23 | C28: 72131601-012 | D28: Restauracion y pintura de porton corredizo existente | E28: unidad de medida: Metros cuadrados presentación: EVENTO | F28: 300 | G28: - | H28: =+VLOOKUP(B28,COSTEO!B:K,10,0) -> 96400 | I28: =H28*300 -> 28920000 | J28: procedencia: Paraguay nro_certificado_origen_nacional: 202460
B29: 24 | C29: 72102201-003 | D29: Bandeja de montaje de instalacion con tapa de 50 cm de ancho x 8 cm de alto. Incluye accesorios para montaje e instalacion. | E29: unidad de medida: Metro lineal presentación: EVENTO | F29: 500 | G29: - | H29: =+VLOOKUP(B29,COSTEO!B:K,10,0) -> 87700 | I29: =H29*500 -> 43850000 | J29: procedencia: Paraguay nro_certificado_origen_nacional: 202461
B30: 25 | C30: 72102201-003 | D30: Bandeja de 5 cm de ancho con accesorios de montaje e instalacion | E30: unidad de medida: Metro lineal presentación: EVENTO | F30: 500 | G30: - | H30: =+VLOOKUP(B30,COSTEO!B:K,10,0) -> 116500 | I30: =H30*500 -> 58250000 | J30: procedencia: Paraguay nro_certificado_origen_nacional: 202462
B31: 26 | C31: 72102201-003 | D31: Conductor nyy 4x2 mm2 | E31: unidad de medida: Metro lineal presentación: EVENTO | F31: 200 | G31: - | H31: =+VLOOKUP(B31,COSTEO!B:K,10,0) -> 20600 | I31: =H31*200 -> 4120000 | J31: procedencia: Paraguay nro_certificado_origen_nacional: 202463
B32: 27 | C32: 72102201-003 | D32: Llave externa de un punto | E32: unidad de medida: Unidad presentación: EVENTO | F32: 44 | G32: - | H32: =+VLOOKUP(B32,COSTEO!B:K,10,0) -> 41200 | I32: =H32*44 -> 1812800 | J32: procedencia: Uruguay nro_certificado_origen_nacional:
B33: 28 | C33: 72102201-003 | D33: Toma tipo nema - toma schuko | E33: unidad de medida: Unidad presentación: EVENTO | F33: 44 | G33: - | H33: =+VLOOKUP(B33,COSTEO!B:K,10,0) -> 41200 | I33: =H33*44 -> 1812800 | J33: procedencia: Uruguay nro_certificado_origen_nacional:
B34: 29 | C34: 72101603-9999 | D34: Mano de obra para instalacion para puntos y tomas | E34: unidad de medida: Unidad presentación: EVENTO | F34: 90 | G34: - | H34: =+VLOOKUP(B34,COSTEO!B:K,10,0) -> 92400 | I34: =H34*90 -> 8316000 | J34: procedencia: Paraguay nro_certificado_origen_nacional: 202459
B35: 30 | C35: 72131601-001 | D35: Adecuacion de cañerias y cables de instalacion electrica existente | E35: unidad de medida: Metro lineal presentación: EVENTO | F35: 400 | G35: - | H35: =+VLOOKUP(B35,COSTEO!B:K,10,0) -> 27000 | I35: =H35*400 -> 10800000 | J35: procedencia: Paraguay nro_certificado_origen_nacional: 202460
B36: 31 | C36: 72102201-003 | D36: Provisi撑 y colocaci撑 de Tablero seccionel plastico | E36: unidad de medida: Unidad presentación: EVENTO | F36: 18 | G36: - | H36: =+VLOOKUP(B36,COSTEO!B:K,10,0) -> 256500 | I36: =H36*18 -> 4617000 | J36: procedencia: Paraguay nro_certificado_origen_nacional: 202461
B37: 32 | C37: 72102201-003 | D37: Proveer e instalar disyuntor Termomatnético tripolar de 80A hasta 100A (llave dentro deltablero) | E37: unidad de medida: Unidad presentación: EVENTO | F37: 18 | G37: - | H37: =+VLOOKUP(B37,COSTEO!B:K,10,0) -> 1170200 | I37: =H37*18 -> 21063600 | J37: procedencia: Paraguay nro_certificado_origen_nacional: 202462
B38: 33 | C38: 30103606-004 | D38: Provisi撑 de Mamparas de tabique tipo eucatex blanco mas vidrio 50%. | E38: unidad de medida: Metros cuadrados presentación: EVENTO | F38: 21 | G38: - | H38: =+VLOOKUP(B38,COSTEO!B:K,10,0) -> 185000 | I38: =H38*21 -> 3885000 | J38: marca: Eucatex fabricante: Eucatex S.A. Indústria e Comércio procedencia: Brasil nro_certificado_origen_nacional:
B39: 34 | C39: 30103606-004 | D39: Mano de Obra - Instalacion de mamparas de tabique tipo eucatex blanco mas vidrio 50%. | E39: unidad de medida: Metros cuadrados presentación: EVENTO | F39: 21 | G39: - | H39: =+VLOOKUP(B39,COSTEO!B:K,10,0) -> 64300 | I39: =H39*21 -> 1350300 | J39: marca: fabricante: procedencia: Paraguay nro_certificado_origen_nacional: 202459
B40: 35 | C40: 72141510-001 | D40: Demalicion sin recuperacion de mamposteria | E40: unidad de medida: Metros cuadrados presentación: EVENTO | F40: 2.7 | G40: - | H40: =+VLOOKUP(B40,COSTEO!B:K,10,0) -> 22200 | I40: =H40*2.7 -> 59940 | J40: procedencia: Paraguay nro_certificado_origen_nacional: 202462
B41: 36 | C41: 72131601-999 | D41: Dintel sobre abertura | E41: unidad de medida: Metro lineal presentación: EVENTO | F41: 2.7 | G41: - | H41: =+VLOOKUP(B41,COSTEO!B:K,10,0) -> 10800 | I41: =H41*2.7 -> 29160 | J41: procedencia: Paraguay nro_certificado_origen_nacional:
B42: 37 | C42: 72101603-9999 | D42: Mano de obra de Dintel sobre abertura | E42: unidad de medida: Metro lineal presentación: EVENTO | F42: 2.7 | G42: - | H42: =+VLOOKUP(B42,COSTEO!B:K,10,0) -> 6000 | I42: =H42*2.7 -> 16200 | J42: procedencia: Paraguay nro_certificado_origen_nacional: 202459
...

Sheet COSTEO
C1: Referencial | D1: =SUM(P15:P65) -> 9.9906354e+08 | J1: factor x ref | K1: 1 | N1: 0.8 | O1: 1 | P1: =+COUNTIF(A:A,O1) -> 17 | Q1: =+SUMIF(A:A,O1,$R$15:$R$65) -> 6441740 | R1: =+Q1/$S$7 -> 0.010057694 | S1: =+COUNTIF(A:A,T1) -> 4 | T1: 11 | U1: 0.3 | V1: =+SUMIF(A:A,T1,$R$15:$R$65) -> 9020200 | W1: =+V1/$S$7 -> 0.014083526
C2: Oferta | D2: =SUM(R15:R65) -> 640478800 | J2: factor x cos | K2: 1 | N2: 0.45 | O2: 2 | P2: =+COUNTIF(A:A,O2) -> 4 | Q2: =+SUMIF(A:A,O2,$R$15:$R$65) -> 23160000 | R2: =+Q2/$S$7 -> 0.036160447 | S2: =+COUNTIF(A:A,T2) -> 0 | T2: 12 | U2: 0.2 | V2: =+SUMIF(A:A,T2,$R$15:$R$65) -> 0 | W2: =+V2/$S$7 -> 0
C3: =IFERROR(__xludf.DUMMYFUNCTION("+R8"),"% del referencial") -> % del referencial | D3: =+D2/D1 -> 0.64107915 | N3: 0.6 | O3: 3 | P3: =+COUNTIF(A:A,O3) -> 8 | Q3: =+SUMIF(A:A,O3,$R$15:$R$65) -> 123913960 | R3: =+Q3/$S$7 -> 0.19347082 | S3: =+COUNTIF(A:A,T3) -> 11 | T3: 13 | U3: 0.5 | V3: =+SUMIF(A:A,T3,$R$15:$R$65) -> 61896100 | W3: =+V3/$S$7 -> 0.096640357
C4: Meta de oferta | D4: =+D1*0.6 -> 5.9943812e+08 | N4: 0.85 | O4: 4 | P4: =+COUNTIF(A:A,O4) -> 5 | Q4: =+SUMIF(A:A,O4,$R$15:$R$65) -> 75229800 | R4: =+Q4/$S$7 -> 0.11745869
C5: Diferencia | D5: =+D1-D4 -> 3.9962542e+08 | N5: 1.15 | O5: 5 | P5: =+COUNTIF(A:A,O5) -> 1 | Q5: =+SUMIF(A:A,O5,$R$15:$R$65) -> 4770000 | R5: =+Q5/$S$7 -> 0.0074475533
N6: 2.8 | O6: 6 | P6: =+COUNTIF(A:A,O6) -> 1 | Q6: =+SUMIF(A:A,O6,$R$15:$R$65) -> 4860000 | R6: =+Q6/$S$7 -> 0.0075880732
D7: Se hace poco | E7: Se hace | F7: Se hace | H7: Se hace muchisimo | P7: =SUM(P1:P6,S1:S3) -> 51 | R7: Oferta | S7: =+D2 -> 640478800
C8: 1 | D8: 2 | E8: 3 | F8: 4 | G8: 5 | H8: 6 | I8: 11 | J8: 12 | K8: 13 | R8: % del referencial | S8: =+S7/D1 -> 0.64107915
C9: =+N1 -> 0.8 | D9: =+N2 -> 0.45 | E9: =+N3 -> 0.6 | F9: =+N4 -> 0.85 | G9: =+N5 -> 1.15 | H9: =+N6 -> 2.8 | I9: =+U1 -> 0.3 | J9: =+U2 -> 0.2 | K9: =+U3 -> 0.5
B11: Licitación: 468573 - MANTENIMIENTO DE DEPOSITOS DE CARGAS AREAS DEL AISP
B13: Grupo 1 - MANTENIMIENTO DE DEPOSITOS DE CARGAS AREAS DEL AISP Contrato Abierto: No, Abastecimiento Simultaneo: No
B14: Ítem | C14: Código Catálogo | D14: Descripción | E14: Atributos | F14: Cantidad | G14: Monto | H14: Precio Unitario (IVA Incluido) | I14: % DEL COSTO | L14: REFERENCIAL unit | N14: % del referencial | O14: COSTO UNITARIO | P14: MONTO TOTAL REFERENCIAL
A15: 6 | B15: 1 | C15: 72141510-001 | D15: Demolicion de contrapiso y piso con aislacion existente. Incluye retiro de escombro | E15: unidad de medida: Metros cuadrados presentación: EVENTO | F15: 900 | G15: - | H15: =+IFERROR(CEILING(HLOOKUP(A15,$B$8:$K$9,2,0)*L15,10),"") -> 29010 | I15: =IFERROR(J15/O15,"") -> 0.11538462 | J15: =IFERROR(K15-O15,"") -> 3000 | K15: =IFERROR(FLOOR(IF(AND((H15-L15)/L15<-0.25,(H15-O15)<0),IF(O15>L15,L15*K$1,K$2*O15),H15),100),"") -> 29000 | L15: 10360 | M15: =IFERROR(K15-H15,"") -> -10 | N15: =IFERROR(H15/L15,"") -> 2.8001931 | O15: 26000 | P15: =+L15*F15 -> 9324000 | Q15: =+O15*F15 -> 23400000 | R15: =IFERROR(K15*F15,"") -> 26100000
A16: 1 | B16: 2 | C16: 72131601-004 | D16: Provision de carpeta | E16: unidad de medida: Metros cuadrados presentación: EVENTO | F16: 900 | G16: - | H16: =+IFERROR(CEILING(HLOOKUP(A16,$B$8:$K$9,2,0)*L16,10),"") -> 11840 | I16: =IFERROR(J16/O16,"") -> 0.084780388 | J16: =IFERROR(K16-O16,"") -> 922.22222 | K16: =IFERROR(FLOOR(IF(AND((H16-L16)/L16<-0.25,(H16-O16)<0),IF(O16>L16,L16*K$1,K$2*O16),H16),100),"") -> 11800 | L16: 14800 | M16: =IFERROR(K16-H16,"") -> -40 | N16: =IFERROR(H16/L16,"") -> 0.8 | O16: =+((65000/50)*5)+(80000*0.02)+((40000/3.6)*0.25) -> 10877.778 | P16: =+L16*F16 -> 13320000 | Q16: =+O16*F16 -> 9790000 | R16: =IFERROR(K16*F16,"") -> 10620000
A17: 5 | B17: 3 | C17: 80111613-9999 | D17: Mano de obra de carpeta | E17: unidad de medida: Metros cuadrados presentación: EVENTO | F17: 900 | G17: - | H17: =+IFERROR(CEILING(HLOOKUP(A17,$B$8:$K$9,2,0)*L17,10),"") -> 25530 | I17: =IFERROR(J17/O17,"") -> -0.203125 | J17: =IFERROR(K17-O17,"") -> -6500 | K17: =IFERROR(FLOOR(IF(AND((H17-L17)/L17<-0.25,(H17-O17)<0),IF(O17>L17,L17*K$1,K$2*O17),H17),100),"") -> 25500 | L17: 22200 | M17: =IFERROR(K17-H17,"") -> -30 | N17: =IFERROR(H17/L17,"") -> 1.15 | O17: 32000 | P17: =+L17*F17 -> 19980000 | Q17: =+O17*F17 -> 28800000 | R17: =IFERROR(K17*F17,"") -> 22950000
A18: 4 | B18: 4 | C18: 72131601-012 | D18: Provision de membrana liquida y tela bidim para aislacion de losa | E18: unidad de medida: Metros cuadrados presentación: EVENTO | F18: 900 | G18: - | H18: =+IFERROR(CEILING(HLOOKUP(A18,$B$8:$K$9,2,0)*L18,10),"") -> 70610 | I18: =IFERROR(J18/O18,"") -> 0.12420382 | J18: =IFERROR(K18-O18,"") -> 7800 | K18: =IFERROR(FLOOR(IF(AND((H18-L18)/L18<-0.25,(H18-O18)<0),IF(O18>L18,L18*K$1,K$2*O18),H18),100),"") -> 70600 | L18: 83063 | M18: =IFERROR(K18-H18,"") -> -10 | N18: =IFERROR(H18/L18,"") -> 0.85007765 | O18: =+((538000/20)*2)+9000 -> 62800 | P18: =+L18*F18 -> 74756700 | Q18: =+O18*F18 -> 56520000 | R18: =IFERROR(K18*F18,"") -> 63540000
A19: 4 | B19: 5 | C19: 80111613-9999 | D19: Mano de obra de membrana liquida y tela bidim para aislacion de losa | E19: unidad de medida: Metros cuadrados presentación: EVENTO | F19: 900 | G19: - | H19: =+IFERROR(CEILING(HLOOKUP(A19,$B$8:$K$9,2,0)*L19,10),"") -> 21360 | I19: =IFERROR(J19/O19,"") -> -0.23928571 | J19: =IFERROR(K19-O19,"") -> -6700 | K19: =IFERROR(FLOOR(IF(AND((H19-L19)/L19<-0.25,(H19-O19)<0),IF(O19>L19,L19*K$1,K$2*O19),H19),100),"") -> 21300 | L19: 25119 | M19: =IFERROR(K19-H19,"") -> -60 | N19: =IFERROR(H19/L19,"") -> 0.85035232 | O19: 28000 | P19: =+L19*F19 -> 22607100 | Q19: =+O19*F19 -> 25200000 | R19: =IFERROR(K19*F19,"") -> 19170000
A20: 2 | B20: 6 | C20: 72103002-002 | D20: Remocion de revoque en zonas deterioradas | E20: unidad de medida: Metros cuadrados presentación: EVENTO | F20: 300 | G20: - | H20: =+IFERROR(CEILING(HLOOKUP(A20,$B$8:$K$9,2,0)*L20,10),"") -> 4780 | I20: =IFERROR(J20/O20,"") -> -0.29333333 | J20: =IFERROR(K20-O20,"") -> -4400 | K20: =IFERROR(FLOOR(IF(AND((H20-L20)/L20<-0.25,(H20-O20)<0),IF(O20>L20,L20*K$1,K$2*O20),H20),100),"") -> 10600 | L20: 10610 | M20: =IFERROR(K20-H20,"") -> 5820 | N20: =IFERROR(H20/L20,"") -> 0.45051838 | O20: 15000 | P20: =+L20*F20 -> 3183000 | Q20: =+O20*F20 -> 4500000 | R20: =IFERROR(K20*F20,"") -> 3180000
A21: 3 | B21: 7 | C21: 72131601-008 | D21: Provision de revoque interior con hidrofugo | E21: unidad de medida: Metros cuadrados presentación: EVENTO | F21: 300 | G21: - | H21: =+IFERROR(CEILING(HLOOKUP(A21,$B$8:$K$9,2,0)*L21,10),"") -> 15900 | I21: =IFERROR(J21/O21,"") -> 0.32745826 | J21: =IFERROR(K21-O21,"") -> 3922.2222 | K21: =IFERROR(FLOOR(IF(AND((H21-L21)/L21<-0.25,(H21-O21)<0),IF(O21>L21,L21*K$1,K$2*O21),H21),100),"") -> 15900 | L21: 26491 | M21: =IFERROR(K21-H21,"") -> 0 | N21: =IFERROR(H21/L21,"") -> 0.60020384 | O21: =+((65000/50)*2)+(80000*0.02)+((40000/3.6)*0.25)+((25000/20)*4) -> 11977.778 | P21: =+L21*F21 -> 7947300 | Q21: =+O21*F21 -> 3593333.3 | R21: =IFERROR(K21*F21,"") -> 4770000
A22: 4 | B22: 8 | C22: 80111613-9999 | D22: Mano de obra - Revoque con hidrófugo | E22: unidad de medida: Metros cuadrados presentación: EVENTO | F22: 300 | G22: - | H22: =+IFERROR(CEILING(HLOOKUP(A22,$B$8:$K$9,2,0)*L22,10),"") -> 28150 | I22: =IFERROR(J22/O22,"") -> 0.0035714286 | J22: =IFERROR(K22-O22,"") -> 100 | K22: =IFERROR(FLOOR(IF(AND((H22-L22)/L22<-0.25,(H22-O22)<0),IF(O22>L22,L22*K$1,K$2*O22),H22),100),"") -> 28100 | L22: 33114 | M22: =IFERROR(K22-H22,"") -> -50 | N22: =IFERROR(H22/L22,"") -> 0.85009362 | O22: 28000 | P22: =+L22*F22 -> 9934200 | Q22: =+O22*F22 -> 8400000 | R22: =IFERROR(K22*F22,"") -> 8430000
A23: 3 | B23: 9 | C23: 72131601-012 | D23: Provision de pintura latex para interior con enduido | E23: unidad de medida: Metros cuadrados presentación: EVENTO | F23: 900 | G23: - | H23: =+IFERROR(CEILING(HLOOKUP(A23,$B$8:$K$9,2,0)*L23,10),"") -> 15330 | I23: =IFERROR(J23/O23,"") -> 0.22387761 | J23: =IFERROR(K23-O23,"") -> 2798.75 | K23: =IFERROR(FLOOR(IF(AND((H23-L23)/L23<-0.25,(H23-O23)<0),IF(O23>L23,L23*K$1,K$2*O23),H23),100),"") -> 15300 | L23: 25539 | M23: =IFERROR(K23-H23,"") -> -30 | N23: =IFERROR(H23/L23,"") -> 0.60025843 | O23: =+((455000/16)*0.3)+((34000/15)*1.2)+(5000*0.25) -> 12501.25 | P23: =+L23*F23 -> 22985100 | Q23: =+O23*F23 -> 11251125 | R23: =IFERROR(K23*F23,"") -> 13770000
A24: 3 | B24: 10 | C24: 80111613-9999 | D24: Mano de obra de pintura latex para interior con enduido | E24: unidad de medida: Metros cuadrados presentación: EVENTO | F24: 900 | G24: - | H24: =+IFERROR(CEILING(HLOOKUP(A24,$B$8:$K$9,2,0)*L24,10),"") -> 24770 | I24: =IFERROR(J24/O24,"") -> 0.64666667 | J24: =IFERROR(K24-O24,"") -> 9700 | K24: =IFERROR(FLOOR(IF(AND((H24-L24)/L24<-0.25,(H24-O24)<0),IF(O24>L24,L24*K$1,K$2*O24),H24),100),"") -> 24700 | L24: 41281 | M24: =IFERROR(K24-H24,"") -> -70 | N24: =IFERROR(H24/L24,"") -> 0.60003391 | O24: 15000 | P24: =+L24*F24 -> 37152900 | Q24: =+O24*F24 -> 13500000 | R24: =IFERROR(K24*F24,"") -> 22230000
A25: 13 | B25: 11 | C25: 72101603-001 | D25: Mantenimiento de canaleta embutida bajada | E25: unidad de medida: Metro lineal presentación: EVENTO | F25: 50 | G25: - | H25: =+IFERROR(CEILING(HLOOKUP(A25,$B$8:$K$9,2,0)*L25,10),"") -> 28700 | I25: =IFERROR(J25/O25,"") -> 0 | J25: =IFERROR(K25-O25,"") -> 0 | K25: =IFERROR(FLOOR(IF(AND((H25-L25)/L25<-0.25,(H25-O25)<0),IF(O25>L25,L25*K$1,K$2*O25),H25),100),"") -> 30000 | L25: 57400 | M25: =IFERROR(K25-H25,"") -> 1300 | N25: =IFERROR(H25/L25,"") -> 0.5 | O25: 30000 | P25: =+L25*F25 -> 2870000 | Q25: =+O25*F25 -> 1500000 | R25: =IFERROR(K25*F25,"") -> 1500000
A26: 2 | B26: 12 | C26: 72101603-9999 | D26: Remocion de canaleta embutida bajada | E26: unidad de medida: Metro lineal presentación: EVENTO | F26: 535 | G26: - | H26: =+IFERROR(CEILING(HLOOKUP(A26,$B$8:$K$9,2,0)*L26,10),"") -> 26700 | I26: =IFERROR(J26/O26,"") -> 0 | J26: =IFERROR(K26-O26,"") -> 0 | K26: =IFERROR(FLOOR(IF(AND((H26-L26)/L26<-0.25,(H26-O26)<0),IF(O26>L26,L26*K$1,K$2*O26),H26),100),"") -> 30000 | L26: 59333 | M26: =IFERROR(K26-H26,"") -> 3300 | N26: =IFERROR(H26/L26,"") -> 0.45000253 | O26: 30000 | P26: =+L26*F26 -> 31743155 | Q26: =+O26*F26 -> 16050000 | R26: =IFERROR(K26*F26,"") -> 16050000
A27: 3 | B27: 13 | C27: 72101603-002 | D27: Provision de Canaleta embutida bajada | E27: unidad de medida: Metro lineal presentación: EVENTO | F27: 535 | G27: - | H27: =+IFERROR(CEILING(HLOOKUP(A27,$B$8:$K$9,2,0)*L27,10),"") -> 147290 | I27: =IFERROR(J27/O27,"") -> 0.051428571 | J27: =IFERROR(K27-O27,"") -> 7200 | K27: =IFERROR(FLOOR(IF(AND((H27-L27)/L27<-0.25,(H27-O27)<0),IF(O27>L27,L27*K$1,K$2*O27),H27),100),"") -> 147200 | L27: 245479 | M27: =IFERROR(K27-H27,"") -> -90 | N27: =IFERROR(H27/L27,"") -> 0.60001059 | O27: 140000 | P27: =+L27*F27 -> 131331265 | Q27: =+O27*F27 -> 74900000 | R27: =IFERROR(K27*F27,"") -> 78752000
A28: 13 | B28: 14 | C28: 72101603-9999 | D28: Mano de obra - instalaci撑 de Canaleta embutida + bajada | E28: unidad de medida: Metro lineal presentación: EVENTO | F28: 535 | G28: - | H28: =+IFERROR(CEILING(HLOOKUP(A28,$B$8:$K$9,2,0)*L28,10),"") -> 51370 | I28: =IFERROR(J28/O28,"") -> 0 | J28: =IFERROR(K28-O28,"") -> 0 | K28: =IFERROR(FLOOR(IF(AND((H28-L28)/L28<-0.25,(H28-O28)<0),IF(O28>L28,L28*K$1,K$2*O28),H28),100),"") -> 75000 | L28: 102733 | M28: =IFERROR(K28-H28,"") -> 23630 | N28: =IFERROR(H28/L28,"") -> 0.50003407 | O28: 75000 | P28: =+L28*F28 -> 54962155 | Q28: =+O28*F28 -> 40125000 | R28: =IFERROR(K28*F28,"") -> 40125000
A29: 11 | B29: 15 | C29: 72102304-9995 | D29: Mantenimiento de registro pluviales | E29: unidad de medida: Metro lineal presentación: EVENTO | F29: 270 | G29: - | H29: =+IFERROR(CEILING(HLOOKUP(A29,$B$8:$K$9,2,0)*L29,10),"") -> 11100 | I29: =IFERROR(J29/O29,"") -> 0 | J29: =IFERROR(K29-O29,"") -> 0 | K29: =IFERROR(FLOOR(IF(AND((H29-L29)/L29<-0.25,(H29-O29)<0),IF(O29>L29,L29*K$1,K$2*O29),H29),100),"") -> 18000 | L29: 37000 | M29: =IFERROR(K29-H29,"") -> 6900 | N29: =IFERROR(H29/L29,"") -> 0.3 | O29: 18000 | P29: =+L29*F29 -> 9990000 | Q29: =+O29*F29 -> 4860000 | R29: =IFERROR(K29*F29,"") -> 4860000
A30: 2 | B30: 16 | C30: 72103002-002 | D30: Remocion de revoque en zona de humedad | E30: unidad de medida: Metros cuadrados presentación: EVENTO | F30: 300 | G30: - | H30: =+IFERROR(CEILING(HLOOKUP(A30,$B$8:$K$9,2,0)*L30,10),"") -> 4670 | I30: =IFERROR(J30/O30,"") -> -0.31333333 | J30: =IFERROR(K30-O30,"") -> -4700 | K30: =IFERROR(FLOOR(IF(AND((H30-L30)/L30<-0.25,(H30-O30)<0),IF(O30>L30,L30*K$1,K$2*O30),H30),100),"") -> 10300 | L30: 10360 | M30: =IFERROR(K30-H30,"") -> 5630 | N30: =IFERROR(H30/L30,"") -> 0.4507722 | O30: 15000 | P30: =+L30*F30 -> 3108000 | Q30: =+O30*F30 -> 4500000 | R30: =IFERROR(K30*F30,"") -> 3090000
A31: 3 | B31: 17 | C31: 72131601-008 | D31: Provision de revoque interior con hidrofugo | E31: unidad de medida: Metros cuadrados presentación: EVENTO | F31: 300 | G31: - | H31: =+IFERROR(CEILING(HLOOKUP(A31,$B$8:$K$9,2,0)*L31,10),"") -> 15900 | I31: =IFERROR(J31/O31,"") -> 0.32745826 | J31: =IFERROR(K31-O31,"") -> 3922.2222 | K31: =IFERROR(FLOOR(IF(AND((H31-L31)/L31<-0.25,(H31-O31)<0),IF(O31>L31,L31*K$1,K$2*O31),H31),100),"") -> 15900 | L31: 26491 | M31: =IFERROR(K31-H31,"") -> 0 | N31: =IFERROR(H31/L31,"") -> 0.60020384 | O31: =+((65000/50)*2)+(80000*0.02)+((40000/3.6)*0.25)+((25000/20)*4) -> 11977.778 | P31: =+L31*F31 -> 7947300 | Q31: =+O31*F31 -> 3593333.3 | R31: =IFERROR(K31*F31,"") -> 4770000
A32: 4 | B32: 18 | C32: 72101603-9999 | D32: Mano de obra - Revoque con hidrófugo | E32: unidad de medida: Metros cuadrados presentación: EVENTO | F32: 300 | G32: - | H32: =+IFERROR(CEILING(HLOOKUP(A32,$B$8:$K$9,2,0)*L32,10),"") -> 28150 | I32: =IFERROR(J32/O32,"") -> 0.0035714286 | J32: =IFERROR(K32-O32,"") -> 100 | K32: =IFERROR(FLOOR(IF(AND((H32-L32)/L32<-0.25,(H32-O32)<0),IF(O32>L32,L32*K$1,K$2*O32),H32),100),"") -> 28100 | L32: 33114 | M32: =IFERROR(K32-H32,"") -> -50 | N32: =IFERROR(H32/L32,"") -> 0.85009362 | O32: 28000 | P32: =+L32*F32 -> 9934200 | Q32: =+O32*F32 -> 8400000 | R32: =IFERROR(K32*F32,"") -> 8430000
A33: 3 | B33: 19 | C33: 72131601-012 | D33: Provision de pintura latex para interior con enduido | E33: unidad de medida: Metros cuadrados presentación: EVENTO | F33: 400 | G33: - | H33: =+IFERROR(CEILING(HLOOKUP(A33,$B$8:$K$9,2,0)*L33,10),"") -> 15330 | I33: =IFERROR(J33/O33,"") -> 0.22387761 | J33: =IFERROR(K33-O33,"") -> 2798.75 | K33: =IFERROR(FLOOR(IF(AND((H33-L33)/L33<-0.25,(H33-O33)<0),IF(O33>L33,L33*K$1,K$2*O33),H33),100),"") -> 15300 | L33: 25539 | M33: =IFERROR(K33-H33,"") -> -30 | N33: =IFERROR(H33/L33,"") -> 0.60025843 | O33: =+((455000/16)*0.3)+((34000/15)*1.2)+(5000*0.25) -> 12501.25 | P33: =+L33*F33 -> 10215600 | Q33: =+O33*F33 -> 5000500 | R33: =IFERROR(K33*F33,"") -> 6120000
A34: 13 | B34: 20 | C34: 72101603-9999 | D34: Mano de obra de pintura latex para interior con enduido | E34: unidad de medida: Metros cuadrados presentación: EVENTO | F34: 400 | G34: - | H34: =+IFERROR(CEILING(HLOOKUP(A34,$B$8:$K$9,2,0)*L34,10),"") -> 20650 | I34: =IFERROR(J34/O34,"") -> 0.37333333 | J34: =IFERROR(K34-O34,"") -> 5600 | K34: =IFERROR(FLOOR(IF(AND((H34-L34)/L34<-0.25,(H34-O34)<0),IF(O34>L34,L34*K$1,K$2*O34),H34),100),"") -> 20600 | L34: 41281 | M34: =IFERROR(K34-H34,"") -> -50 | N34: =IFERROR(H34/L34,"") -> 0.50023013 | O34: 15000 | P34: =+L34*F34 -> 16512400 | Q34: =+O34*F34 -> 6000000 | R34: =IFERROR(K34*F34,"") -> 8240000
A35: 1 | B35: 21 | C35: 72131601-012 | D35: Provision de pintura latex para exterior | E35: unidad de medida: Metros cuadrados presentación: EVENTO | F35: 2000 | G35: - | H35: =+IFERROR(CEILING(HLOOKUP(A35,$B$8:$K$9,2,0)*L35,10),"") -> 20440 | I35: =IFERROR(J35/O35,"") -> 0.10824392 | J35: =IFERROR(K35-O35,"") -> 1992.5 | K35: =IFERROR(FLOOR(IF(AND((H35-L35)/L35<-0.25,(H35-O35)<0),IF(O35>L35,L35*K$1,K$2*O35),H35),100),"") -> 20400 | L35: 25539 | M35: =IFERROR(K35-H35,"") -> -40 | N35: =IFERROR(H35/L35,"") -> 0.80034457 | O35: =+((770000/16)*0.3)+((34000/15)*1.2)+(5000*0.25) -> 18407.5 | P35: =+L35*F35 -> 51078000 | Q35: =+O35*F35 -> 36815000 | R35: =IFERROR(K35*F35,"") -> 40800000
A36: 3 | B36: 22 | C36: 72101603-9999 | D36: Mano de obra de pintura latex para exterior | E36: unidad de medida: Metros cuadrados presentación: EVENTO | F36: 2000 | G36: - | H36: =+IFERROR(CEILING(HLOOKUP(A36,$B$8:$K$9,2,0)*L36,10),"") -> 19850 | I36: =IFERROR(J36/O36,"") -> 0.32 | J36: =IFERROR(K36-O36,"") -> 4800 | K36: =IFERROR(FLOOR(IF(AND((H36-L36)/L36<-0.25,(H36-O36)<0),IF(O36>L36,L36*K$1,K$2*O36),H36),100),"") -> 19800 | L36: 33075 | M36: =IFERROR(K36-H36,"") -> -50 | N36: =IFERROR(H36/L36,"") -> 0.60015117 | O36: 15000 | P36: =+L36*F36 -> 66150000 | Q36: =+O36*F36 -> 30000000 | R36: =IFERROR(K36*F36,"") -> 39600000
A37: 4 | B37: 23 | C37: 72131601-012 | D37: Restauracion y pintura de porton corredizo existente | E37: unidad de medida: Metros cuadrados presentación: EVENTO | F37: 300 | G37: - | H37: =+IFERROR(CEILING(HLOOKUP(A37,$B$8:$K$9,2,0)*L37,10),"") -> 96480 | I37: =IFERROR(J37/O37,"") -> 0.20332871 | J37: =IFERROR(K37-O37,"") -> 16288.889 | K37: =IFERROR(FLOOR(IF(AND((H37-L37)/L37<-0.25,(H37-O37)<0),IF(O37>L37,L37*K$1,K$2*O37),H37),100),"") -> 96400 | L37: 113500 | M37: =IFERROR(K37-H37,"") -> -80 | N37: =IFERROR(H37/L37,"") -> 0.85004405 | O37: =+((380000/3.6)*0.2*2)+((160000/3.6)*0.1*2)+28000+((6*50000)/300) -> 80111.111 | P37: =+L37*F37 -> 34050000 | Q37: =+O37*F37 -> 24033333 | R37: =IFERROR(K37*F37,"") -> 28920000
A38: 11 | B38: 24 | C38: 72102201-003 | D38: Bandeja de montaje de instalacion con tapa de 50 cm de ancho x 8 cm de alto. Incluye accesorios para montaje e instalacion. | E38: unidad de medida: Metro lineal presentación: EVENTO | F38: 500 | G38: - | H38: =+IFERROR(CEILING(HLOOKUP(A38,$B$8:$K$9,2,0)*L38,10),"") -> 87760 | I38: =IFERROR(J38/O38,"") -> 0.0524 | J38: =IFERROR(K38-O38,"") -> 4366.6667 | K38: =IFERROR(FLOOR(IF(AND((H38-L38)/L38<-0.25,(H38-O38)<0),IF(O38>L38,L38*K$1,K$2*O38),H38),100),"") -> 87700 | L38: 292530 | M38: =IFERROR(K38-H38,"") -> -60 | N38: =IFERROR(H38/L38,"") -> 0.30000342 | O38: =250000/3 -> 83333.333 | P38: =+L38*F38 -> 146265000 | Q38: =+O38*F38 -> 41666667 | R38: =IFERROR(K38*F38,"") -> 43850000
A39: 13 | B39: 25 | C39: 72102201-003 | D39: Bandeja de 5 cm de ancho con accesorios de montaje e instalacion | E39: unidad de medida: Metro lineal presentación: EVENTO | F39: 500 | G39: - | H39: =+IFERROR(CEILING(HLOOKUP(A39,$B$8:$K$9,2,0)*L39,10),"") -> 116550 | I39: =IFERROR(J39/O39,"") -> 0.39800559 | J39: =IFERROR(K39-O39,"") -> 33167 | K39: =IFERROR(FLOOR(IF(AND((H39-L39)/L39<-0.25,(H39-O39)<0),IF(O39>L39,L39*K$1,K$2*O39),H39),100),"") -> 116500 | L39: 233100 | M39: =IFERROR(K39-H39,"") -> -50 | N39: =IFERROR(H39/L39,"") -> 0.5 | O39: 83333 | P39: =+L39*F39 -> 116550000 | Q39: =+O39*F39 -> 41666500 | R39: =IFERROR(K39*F39,"") -> 58250000
A40: 1 | B40: 26 | C40: 72102201-003 | D40: Conductor nyy 4x2 mm2 | E40: unidad de medida: Metro lineal presentación: EVENTO | F40: 200 | G40: - | H40: =+IFERROR(CEILING(HLOOKUP(A40,$B$8:$K$9,2,0)*L40,10),"") -> 20610 | I40: =IFERROR(J40/O40,"") -> 0.2875 | J40: =IFERROR(K40-O40,"") -> 4600 | K40: =IFERROR(FLOOR(IF(AND((H40-L40)/L40<-0.25,(H40-O40)<0),IF(O40>L40,L40*K$1,K$2*O40),H40),100),"") -> 20600 | L40: 25761 | M40: =IFERROR(K40-H40,"") -> -10 | N40: =IFERROR(H40/L40,"") -> 0.80004658 | O40: =16000 -> 16000 | P40: =+L40*F40 -> 5152200 | Q40: =+O40*F40 -> 3200000 | R40: =IFERROR(K40*F40,"") -> 4120000
A41: 1 | B41: 27 | C41: 72102201-003 | D41: Llave externa de un punto | E41: unidad de medida: Unidad presentación: EVENTO | F41: 44 | G41: - | H41: =+IFERROR(CEILING(HLOOKUP(A41,$B$8:$K$9,2,0)*L41,10),"") -> 41220 | I41: =IFERROR(J41/O41,"") -> 1.0497512 | J41: =IFERROR(K41-O41,"") -> 21100 | K41: =IFERROR(FLOOR(IF(AND((H41-L41)/L41<-0.25,(H41-O41)<0),IF(O41>L41,L41*K$1,K$2*O41),H41),100),"") -> 41200 | L41: 51522 | M41: =IFERROR(K41-H41,"") -> -20 | N41: =IFERROR(H41/L41,"") -> 0.80004658 | O41: =11000+9100 -> 20100 | P41: =+L41*F41 -> 2266968 | Q41: =+O41*F41 -> 884400 | R41: =IFERROR(K41*F41,"") -> 1812800
A42: 1 | B42: 28 | C42: 72102201-003 | D42: Toma tipo nema - toma schuko | E42: unidad de medida: Unidad presentación: EVENTO | F42: 44 | G42: - | H42: =+IFERROR(CEILING(HLOOKUP(A42,$B$8:$K$9,2,0)*L42,10),"") -> 41220 | I42: =IFERROR(J42/O42,"") -> 0.15730337 | J42: =IFERROR(K42-O42,"") -> 5600 | K42: =IFERROR(FLOOR(IF(AND((H42-L42)/L42<-0.25,(H42-O42)<0),IF(O42>L42,L42*K$1,K$2*O42),H42),100),"") -> 41200 | L42: 51522 | M42: =IFERROR(K42-H42,"") -> -20 | N42: =IFERROR(H42/L42,"") -> 0.80004658 | O42: =26500+9100 -> 35600 | P42: =+L42*F42 -> 2266968 | Q42: =+O42*F42 -> 1566400 | R42: =IFERROR(K42*F42,"") -> 1812800
...

Sheet analisis ref
C3: EMPRESA | D3: ID | E3: TIPO DE CONTRATO | F3: MONTO REFERENCIA | G3: MONTO OFERENTE | H3: % REFERENCIAL | I3: OBS
C4: MURA S.A | D4: - | E4: - | F4: - | G4: - | H4: =G4/F4 -> #VALUE! | I4: NO POSEE PARTICIPACIONES
C5: CORPORACION LEMURIA | D5: 444766 | E5: ABIERTO | F5: 73829687 | G5: 34201906 | H5: =G5/F5 -> 0.46325411
C6: CARLOS ALBERTO PERALES ORTELLADO (COIN) | D6: 460117 | E6: ABIERTO | F6: 338456817 | G6: 165786276 | H6: =G6/F6 -> 0.48982992
C7: CARLOS ALBERTO PERALES ORTELLADO (COIN) | D7: 464425 | E7: ABIERTO | F7: 304613483 | G7: 157975972 | H7: =G7/F7 -> 0.51861123
C8: D Y D ARQUITECTURA Y CONSTRUCCION SRL | D8: 466754 | E8: ABIERTO | F8: 16856293 | G8: 8745895 | H8: =G8/F8 -> 0.51885044
C9: CORPORACION LEMURIA | D9: 447685 | E9: ABIERTO | F9: 115213628 | G9: 61415428 | H9: =G9/F9 -> 0.53305697
C10: ENGINEERIN SAECA | D10: 399552 | E10: ABIERTO | F10: 178045124 | G10: 98855028 | H10: =G10/F10 -> 0.55522457
C11: CARLOS ALBERTO PERALES ORTELLADO (COIN) | D11: 459933 | E11: ABIERTO | F11: 227432961 | G11: 135964650 | H11: =G11/F11 -> 0.59782298
C12: NELSON FEDERICO SEGOVIA AZUCAS (EN OBRAS) | D12: 462710 | E12: ABIERTO | F12: 6944250 | G12: 4677400 | H12: =G12/F12 -> 0.67356446
C13: DIEGO SZKLARKIERVICZ KALLER | D13: 430108 | E13: ABIERTO | F13: 24389702 | G13: 16620413 | H13: =G13/F13 -> 0.68145207
C14: ENGINEERIN SAECA | D14: 400455 | E14: ABIERTO | F14: =142919506*3 -> 428758518 | G14: 310319406 | H14: =G14/F14 -> 0.72376266 | I14: NO ADJUDICADO
C15: DIEGO SZKLARKIERVICZ KALLER | D15: 435528 | E15: ABIERTO | F15: 205704200 | G15: 154168630 | H15: =G15/F15 -> 0.74946759
C16: EJ INGENIERIA | D16: 443707 | E16: ABIERTO | F16: 83530853 | G16: 63000000 | H16: =G16/F16 -> 0.75421234
C17: D Y D ARQUITECTURA Y CONSTRUCCION SRL | D17: 415092 | E17: ABIERTO | F17: 130183748 | G17: 103100000 | H17: =G17/F17 -> 0.79195753
C18: DIEGO SZKLARKIERVICZ KALLER | D18: 422961 | E18: ABIERTO | F18: 45844680 | G18: 36675744 | H18: =G18/F18 -> 0.8
C19: ING. JULIO C. GOMEZ | D19: 440855 | E19: ABIERTO | F19: =753854+837428+178075+82891 -> 1852248 | G19: 1489760 | H19: =G19/F19 -> 0.80429834
C20: D Y D ARQUITECTURA Y CONSTRUCCION SRL | D20: 459845 | E20: ABIERTO | F20: 280382512 | G20: 233731277 | H20: =G20/F20 -> 0.83361575
C21: HUGO GIOVINE | D21: 374082 | E21: ABIERTO | F21: 20112000 | G21: 16994040 | H21: =G21/F21 -> 0.84497017
C22: EJ INGENIERIA | D22: 434746 | E22: ABIERTO | F22: 101416574 | G22: 99047652 | H22: =G22/F22 -> 0.97664167
C23: D Y D ARQUITECTURA Y CONSTRUCCION SRL | D23: 436132 | E23: ABIERTO | F23: 266031733 | G23: 289728202 | H23: =G23/F23 -> 1.0890738
C24: HUGO NAVARRO | D24: 460696 | E24: CERRADO | F24: 181286405 | G24: 112401900 | H24: =G24/F24 -> 0.62002388 | I24: =H24/G24 -> 5.5161334e-09
C25: HUGO GIOVINE | D25: 417180 | E25: CERRADO | F25: =573465500+696129360 -> 1269594860 | G25: 814919238 | H25: =G25/F25 -> 0.64187345
C26: HUGO NAVARRO | D26: 465495 | E26: CERRADO | F26: 70467655 | G26: 47960320 | H26: =G26/F26 -> 0.68060048 | I26: NO POSEE PARTICIPACIONES
C27: ING. JULIO C. GOMEZ | D27: 419207 | E27: CERRADO | F27: 980017800 | G27: 687022410 | H27: =G27/F27 -> 0.70103054
C28: HUGO GIOVINE | D28: 445665 | E28: CERRADO | F28: 135146007 | G28: 98523290 | H28: =G28/F28 -> 0.7290137
C29: NELSON FEDERICO SEGOVIA AZUCAS (EN OBRAS) | D29: 448198 | E29: CERRADO | F29: =2820063420+992010955 -> 3812074375 | G29: =2249422900+737860100 -> 2987283000 | H29: =G29/F29 -> 0.78363712
C30: ING. JULIO C. GOMEZ | D30: 441613 | E30: CERRADO | F30: 6.7695395e+08 | G30: 541769366 | H30: =G30/F30 -> 0.80030461
C31: NELSON FEDERICO SEGOVIA AZUCAS (EN OBRAS) | D31: 448490 | E31: CERRADO | F31: =702292287+199998000 -> 902290287 | G31: 722300268 | H31: =G31/F31 -> 0.80051872
C32: HUGO GIOVINE | D32: 457482 | E32: CERRADO | F32: 590866043 | G32: 484073658 | H32: =G32/F32 -> 0.81926126
C33: CORPORACION LEMURIA | D33: 459720 | E33: CERRADO | F33: =83380987+174272741 -> 257653728 | G33: 219605550 | H33: =G33/F33 -> 0.85232825
C34: JL Y COMPAÑIA | D34: 435545 | E34: CERRADO | F34: 5.407314e+08 | G34: 464734131 | H34: =G34/F34 -> 0.85945467
C35: JL Y COMPAÑIA | D35: 419188 | E35: CERRADO | F35: 57572341 | G35: 50663596 | H35: =G35/F35 -> 0.87999889
C36: HUGO NAVARRO | D36: 443130 | E36: CERRADO | F36: 3.8223676e+08 | G36: 351487488 | H36: =G36/F36 -> 0.91955438
C37: CORPORACION LEMURIA | D37: 461244 | E37: CERRADO | F37: 4581676142 | G37: 4261358488 | H37: =G37/F37 -> 0.93008723
C38: EL JAMSA DORADO S.A | D38: 435895 | E38: CERRADO | F38: 2.0445424e+08 | G38: 190211270 | H38: =G38/F38 -> 0.93033663 | I38: NO POSEE ADJUDICACIONES, SI PARTICIPACIONES
C39: YUKON S.A | D39: 374318 | E39: CERRADO | F39: 151095000 | G39: 141800000 | H39: =G39/F39 -> 0.93848241
C40: EL JAMSA DORADO S.A | D40: 436064 | E40: CERRADO | F40: 280007850 | G40: 269716480 | H40: =G40/F40 -> 0.96324614 | I40: NO POSEE ADJUDICACIONES, SI PARTICIPACIONES
C41: YUKON S.A | D41: 417711 | E41: CERRADO | F41: 185797500 | G41: 181250550 | H41: =G41/F41 -> 0.97552739
C42: TES INGENIERIA | D42: 432873 | E42: CERRADO | F42: 187549923 | G42: 183745310 | H42: =G42/F42 -> 0.97971413
...
