Workbook
Name A: COSTEO!$X$17
Name O: COSTEO!$X$15
Name P: COSTEO!$X$14
Name SO: COSTEO!$X$16
Name SP: COSTEO!$X$13

Sheet OFERTA
A1: Licitación: 463576 - MANTENIMIENTO PREVENTIVO Y CORRECTIVO DE GRUPO GENERADOR - CONTRATO ABIERTO PLURIANUAL
A3: Grupo 1 - MANTENIMIENTO PREVENTIVO Y CORRECTIVO DE GENERADOR CATERPILLAR GEP88 DE 88KVA. Contrato Abierto: Por Monto (Mínimo: 50000000 Máximo: 100000000), Abastecimiento Simultaneo: No
A4: Ítem | B4: Código Catálogo | C4: Descripción | D4: Atributos | E4: Cantidad | F4: Monto | G4: Precio Unitario (IVA Incluido) | H4: Precio Total | I4: Caracteristicas
A5: 1 | B5: 80111613-9999 | C5: Mano de obra p/ cambio de filtro de aire. | D5: unidad de medida: Unidad presentación: EVENTO | E5: 1 | F5: mínimo: 0,00 máximo: 0,00 | G5: =+VLOOKUP(A5,COSTEO!B:O,10,0) -> 187900 | H5: =G5*1 -> 187900 | I5: procedencia: Paraguay
A6: 2 | B6: 80111613-9999 | C6: Mano de obra p/cambio de filtro de aceite. | D6: unidad de medida: Unidad presentación: EVENTO | E6: 1 | F6: mínimo: 0,00 máximo: 0,00 | G6: =+VLOOKUP(A6,COSTEO!B:O,10,0) -> 180200 | H6: =G6*1 -> 180200 | I6: procedencia: Paraguay
A7: 3 | B7: 80111613-9999 | C7: Mano de obra p/ Cambio de filtro de combustible. | D7: unidad de medida: Unidad presentación: EVENTO | E7: 1 | F7: mínimo: 0,00 máximo: 0,00 | G7: =+VLOOKUP(A7,COSTEO!B:O,10,0) -> 170600 | H7: =G7*1 -> 170600 | I7: procedencia: Paraguay
A8: 4 | B8: 80111613-9999 | C8: Mano de obra p/ cambio de aceite de motor. | D8: unidad de medida: Unidad presentación: EVENTO | E8: 1 | F8: mínimo: 0,00 máximo: 0,00 | G8: =+VLOOKUP(A8,COSTEO!B:O,10,0) -> 199400 | H8: =G8*1 -> 199400 | I8: procedencia: Paraguay
A9: 5 | B9: 80111613-9999 | C9: Mano de obra p/ cambio de refrigerante para radiador. | D9: unidad de medida: Unidad presentación: EVENTO | E9: 1 | F9: mínimo: 0,00 máximo: 0,00 | G9: =+VLOOKUP(A9,COSTEO!B:O,10,0) -> 201300 | H9: =G9*1 -> 201300 | I9: procedencia: Paraguay
A10: 6 | B10: 72102201-006 | C10: Revisi｢n y ajustes de sistema elＤtrico del panel de control del generador. | D10: unidad de medida: Unidad presentación: EVENTO | E10: 1 | F10: mínimo: 0,00 máximo: 0,00 | G10: =+VLOOKUP(A10,COSTEO!B:O,10,0) -> 80600 | H10: =G10*1 -> 80600 | I10: procedencia: Paraguay
A11: 7 | B11: 72102201-006 | C11: Control del estado de los sistemas del equipo: Combustible, ventilaci｢n, lubricaci｢n y arranque. | D11: unidad de medida: Unidad presentación: EVENTO | E11: 1 | F11: mínimo: 0,00 máximo: 0,00 | G11: =+VLOOKUP(A11,COSTEO!B:O,10,0) -> 68500 | H11: =G11*1 -> 68500 | I11: procedencia: Paraguay
A12: 8 | B12: 72102201-006 | C12: Revisiвn del estado de parаmetros mecаnicos (presiвn de aceite, temperatura, RPM) | D12: unidad de medida: Unidad presentación: EVENTO | E12: 1 | F12: mínimo: 0,00 máximo: 0,00 | G12: =+VLOOKUP(A12,COSTEO!B:O,10,0) -> 70700 | H12: =G12*1 -> 70700 | I12: procedencia: Paraguay
A13: 9 | B13: 72102201-006 | C13: Revisiвn del estado de parаmetros elВctricos (tensiвn, frecuencia) | D13: unidad de medida: Unidad presentación: EVENTO | E13: 1 | F13: mínimo: 0,00 máximo: 0,00 | G13: =+VLOOKUP(A13,COSTEO!B:O,10,0) -> 58400 | H13: =G13*1 -> 58400 | I13: procedencia: Paraguay
A14: 10 | B14: 72102201-006 | C14: Chequeo de funcionamiento del indicador de nivel de combustible y del indicador del filtro de aire. | D14: unidad de medida: Unidad presentación: EVENTO | E14: 1 | F14: mínimo: 0,00 máximo: 0,00 | G14: =+VLOOKUP(A14,COSTEO!B:O,10,0) -> 46800 | H14: =G14*1 -> 46800 | I14: procedencia: Paraguay
A15: 11 | B15: 72102201-006 | C15: Chequeo de cables sueltos flojos, pelados, quemados, da兀dos, terminales flojos. | D15: unidad de medida: Unidad presentación: EVENTO | E15: 1 | F15: mínimo: 0,00 máximo: 0,00 | G15: =+VLOOKUP(A15,COSTEO!B:O,10,0) -> 5400 | H15: =G15*1 -> 5400 | I15: procedencia: Paraguay
A16: 12 | B16: 72102201-006 | C16: Chequeo de protectores en mal estado o flojos, ajuste de soportes. | D16: unidad de medida: Unidad presentación: EVENTO | E16: 1 | F16: mínimo: 0,00 máximo: 0,00 | G16: =+VLOOKUP(A16,COSTEO!B:O,10,0) -> 86600 | H16: =G16*1 -> 86600 | I16: procedencia: Paraguay
... A46: 42 | B46: 72102201-006 | C46: Provisi｢n y cambio de terminales para bater｡a | D46: unidad de medida: Unidad presentación: EVENTO | E46: 1 | F46: mínimo: 0,00 máximo: 0,00 | G46: =+VLOOKUP(A46,COSTEO!B:O,10,0) -> 75000 | H46: =G46*1 -> 75000 | I46: procedencia: Estados unidos
G47: Total por Grupo: | H47: =H5+H6+H7+H8+H9+H10+H11+H12+H13+H14+H15+H16+H17+H18+H19+H20+H21+H22+H23+H24+H25+H26+H27+H28+H29+H30+H31+H32+H33+H34+H35+H36+H37+H38+H39+H40+H41+H42+H43+H44+H45+H46 -> 21578700
G50: Total General Calculado: | H50: =H47 -> 21578700
B54: Firma
B55: Nombre: | C55: Lorena Estefania Silva Ruiz
B56: En calidad de: | C56: Representante legal de IBL Ingeniería SRL

Sheet COSTEO
C1: Referencial | D1: =SUM(L15:L1180) -> 39503513 | E1: =+E2-D2 -> 0 | F1: 0.47 | J1: factor x ref | K1: 0.75 | M1: 0.07 | N1: 1 | P1: =+$O1/$O$7 -> 0 | Q1: =+SUMIF(A:A,N1,K:K) -> 6407000 | R1: =+$Q1/$R$7 -> 0.29691316 | S1: 0.06 | T1: 11 | U1: =+COUNTIF(A:A,11) -> 0 | V1: =+$U1/$O$7 -> 0 | W1: =+SUMIF(A:A,T1,K:K) -> 0 | X1: =+$W1/$R$7 -> 0
C2: Oferta | D2: =+K57 -> 21578700 | E2: =+K57 -> 21578700 | J2: factor x cos | K2: 0.5 | M2: 0.24 | N2: 2 | P2: =+$O2/$O$7 -> 0 | Q2: =+SUMIF(A:A,N2,K:K) -> 4884800 | R2: =+$Q2/$R$7 -> 0.22637138 | S2: 0.06 | T2: 12 | U2: =+COUNTIF(A:A,12) -> 0 | V2: =+$U2/$O$7 -> 0 | W2: =+SUMIF(A:A,T2,K:K) -> 0 | X2: =+$W2/$R$7 -> 0
C3: =+Q8 -> % del referencial | D3: =+R8 -> 0.54624762 | E3: =+E2/D1 -> 0.54624762 | M3: 0.37 | N3: 3 | P3: =+$O3/$O$7 -> 0 | Q3: =+SUMIF(A:A,N3,K:K) -> 413700 | R3: =+$Q3/$R$7 -> 0.019171683 | S3: 0.04 | T3: 13 | U3: =+COUNTIF(A:A,13) -> 1 | V3: =+$U3/$O$7 -> 0.023809524 | W3: =+SUMIF(A:A,T3,K:K) -> 2796300 | X3: =+$W3/$R$7 -> 0.12958612
C4: Meta de oferta | D4: =+D1*F1 -> 18566651 | M4: 0.62 | N4: 4 | P4: =+$O4/$O$7 -> 0 | Q4: =+SUMIF(A:A,N4,K:K) -> 4445500 | R4: =+$Q4/$R$7 -> 0.20601334
C5: Diferencia | D5: =+D2-D4 -> 3012048.9 | M5: 0.9 | N5: 5 | P5: =+$O5/$O$7 -> 0 | Q5: =+SUMIF(A:A,N5,K:K) -> 0 | R5: =+$Q5/$R$7 -> 0
M6: 1.15 | N6: 6 | P6: =+$O6/$O$7 -> 0 | Q6: =+SUMIF(A:A,N6,K:K) -> 2631400 | R6: =+$Q6/$R$7 -> 0.12194432
D7: Se hace poco | F7: Se hace | H7: Se hace muchisimo | I7: No mires | K7: No entendes?. NO MIRES | O7: 42 | Q7: Oferta | R7: =SUM(Q1:Q6)+SUM(W1:W3) -> 21578700
C8: 1 | D8: 2 | E8: 3 | F8: 4 | G8: 5 | H8: 6 | I8: 11 | J8: 12 | K8: 13 | Q8: % del referencial | R8: =+D2/D1 -> 0.54624762
C9: 0.07 | D9: =+M2 -> 0.24 | E9: =+M3 -> 0.37 | F9: =+M4 -> 0.62 | G9: =+M5 -> 0.9 | H9: =+M6 -> 1.15 | I9: =+S1 -> 0.06 | J9: =+S2 -> 0.06 | K9: 0.04
B11: Licitación: 463576 - MANTENIMIENTO PREVENTIVO Y CORRECTIVO DE GRUPO GENERADOR - CONTRATO ABIERTO PLURIANUAL | L11: PRECIO REFERENCIAL | M11: COSTO DE MATERIALES | N11: COSTO DE MANO DE OBRA | O11: COSTO TOTAL | T11: Costo de MDO
T12: Descripción | U12: Cantidad | V12: Costo unitario | W12: Costo total | X12: Jornal con IPS | Y12: Costo total con IPS
B13: Grupo 1 - MANTENIMIENTO PREVENTIVO Y CORRECTIVO DE GENERADOR CATERPILLAR GEP88 DE 88KVA. Contrato Abierto: Por Monto (Mínimo: 50000000 Máximo: 100000000), Abastecimiento Simultaneo: No | T13: Supervisor | U13: 1 | V13: =5500000/30 -> 183333.33 | W13: =+V13*U13 -> 183333.33 | X13: =+V13+21500 -> 204833.33 | Y13: =+U13*X13 -> 204833.33
B14: Ítem | C14: Código Catálogo | D14: Descripción | E14: Atributos | F14: Cantidad | G14: Monto | H14: Precio Unitario (IVA Incluido) | I14: Precio Total | J14: Caracteristicas | T14: Puntero | U14: 1 | V14: 185000 | W14: =+V14*U14 -> 185000 | X14: =+V14+21500 -> 206500 | Y14: =+U14*X14 -> 206500
A15: 6 | B15: 1 | C15: 80111613-9999 | D15: Mano de obra p/ cambio de filtro de aire. | E15: unidad de medida: Unidad presentación: EVENTO | F15: 1 | G15: mínimo: 0,00 máximo: 0,00 | H15: =+IFERROR(CEILING(HLOOKUP(A15,$C$8:$K$9,2,0)*L15,100),"") -> 187900 | I15: =IFERROR(H15*1,"") -> 187900 | J15: procedencia: | K15: =IFERROR(FLOOR(IF(AND((H15-L15)/L15<-0.25,(H15-O15)<0),IF(O15>L15,L15*K$1,K$2*O15),H15),100),"") -> 187900 | L15: 163333 | N15: =((SO+O)/8)*(45/60)+((P/9*5)/22) -> 34558.396 | O15: =SUM(M15:N15) -> 34558.396 | P15: =+K15/O15 -> 5.4371736 | Q15: =+K15/L15 -> 1.1504105 | R15: =+K15-O15 -> 153341.6 | T15: Oficial | U15: 1 | V15: 150000 | W15: =+V15*U15 -> 150000 | X15: =+V15+21500 -> 171500 | Y15: =+U15*X15 -> 171500
A16: 6 | B16: 2 | C16: 80111613-9999 | D16: Mano de obra p/cambio de filtro de aceite. | E16: unidad de medida: Unidad presentación: EVENTO | F16: 1 | G16: mínimo: 0,00 máximo: 0,00 | H16: =+IFERROR(CEILING(HLOOKUP(A16,$C$8:$K$9,2,0)*L16,100),"") -> 180200 | I16: =IFERROR(H16*1,"") -> 180200 | J16: procedencia: | K16: =IFERROR(FLOOR(IF(AND((H16-L16)/L16<-0.25,(H16-O16)<0),IF(O16>L16,L16*K$1,K$2*O16),H16),100),"") -> 180200 | L16: 156667 | N16: =((SO+O)/8)*(45/60)+((P/9*5)/22) -> 34558.396 | O16: =SUM(M16:N16) -> 34558.396 | P16: =+K16/O16 -> 5.2143623 | Q16: =+K16/L16 -> 1.1502103 | R16: =+K16-O16 -> 145641.6 | T16: Semioficial | U16: 1 | V16: 120000 | W16: =+V16*U16 -> 120000 | X16: =+V16+21500 -> 141500 | Y16: =+U16*X16 -> 141500
A17: 6 | B17: 3 | C17: 80111613-9999 | D17: Mano de obra p/ Cambio de filtro de combustible. | E17: unidad de medida: Unidad presentación: EVENTO | F17: 1 | G17: mínimo: 0,00 máximo: 0,00 | H17: =+IFERROR(CEILING(HLOOKUP(A17,$C$8:$K$9,2,0)*L17,100),"") -> 170600 | I17: =IFERROR(H17*1,"") -> 170600 | J17: procedencia: | K17: =IFERROR(FLOOR(IF(AND((H17-L17)/L17<-0.25,(H17-O17)<0),IF(O17>L17,L17*K$1,K$2*O17),H17),100),"") -> 170600 | L17: 148333 | N17: =((SO+O)/8)*(45/60)+((P/9*5)/22) -> 34558.396 | O17: =SUM(M17:N17) -> 34558.396 | P17: =+K17/O17 -> 4.9365716 | Q17: =+K17/L17 -> 1.1501149 | R17: =+K17-O17 -> 136041.6 | T17: Ayudante | U17: 1 | V17: 105000 | W17: =+V17*U17 -> 105000 | X17: =+V17+21500 -> 126500 | Y17: =+U17*X17 -> 126500
A18: 6 | B18: 4 | C18: 80111613-9999 | D18: Mano de obra p/ cambio de aceite de motor. | E18: unidad de medida: Unidad presentación: EVENTO | F18: 1 | G18: mínimo: 0,00 máximo: 0,00 | H18: =+IFERROR(CEILING(HLOOKUP(A18,$C$8:$K$9,2,0)*L18,100),"") -> 199400 | I18: =IFERROR(H18*1,"") -> 199400 | J18: procedencia: | K18: =IFERROR(FLOOR(IF(AND((H18-L18)/L18<-0.25,(H18-O18)<0),IF(O18>L18,L18*K$1,K$2*O18),H18),100),"") -> 199400 | L18: 173333 | N18: =((SO+O)/8)*(45/60)+((P/9*5)/22) -> 34558.396 | O18: =SUM(M18:N18) -> 34558.396 | P18: =+K18/O18 -> 5.7699436 | Q18: =+K18/L18 -> 1.1503868 | R18: =+K18-O18 -> 164841.6
A19: 6 | B19: 5 | C19: 80111613-9999 | D19: Mano de obra p/ cambio de refrigerante para radiador. | E19: unidad de medida: Unidad presentación: EVENTO | F19: 1 | G19: mínimo: 0,00 máximo: 0,00 | H19: =+IFERROR(CEILING(HLOOKUP(A19,$C$8:$K$9,2,0)*L19,100),"") -> 201300 | I19: =IFERROR(H19*1,"") -> 201300 | J19: procedencia: | K19: =IFERROR(FLOOR(IF(AND((H19-L19)/L19<-0.25,(H19-O19)<0),IF(O19>L19,L19*K$1,K$2*O19),H19),100),"") -> 201300 | L19: 175000 | N19: =((SO+O)/8)*(45/60)+((P/9*5)/22) -> 34558.396 | O19: =SUM(M19:N19) -> 34558.396 | P19: =+K19/O19 -> 5.824923 | Q19: =+K19/L19 -> 1.1502857 | R19: =+K19-O19 -> 166741.6 | T19: Costo por dia | W19: =SUM(W14:W17) -> 560000 | Y19: =SUM(Y14:Y17) -> 646000
A20: 3 | B20: 6 | C20: 72102201-006 | D20: Revisi｢n y ajustes de sistema elＤtrico del panel de control del generador. | E20: unidad de medida: Unidad presentación: EVENTO | F20: 1 | G20: mínimo: 0,00 máximo: 0,00 | H20: =+IFERROR(CEILING(HLOOKUP(A20,$C$8:$K$9,2,0)*L20,100),"") -> 80600 | I20: =IFERROR(H20*1,"") -> 80600 | J20: procedencia: | K20: =IFERROR(FLOOR(IF(AND((H20-L20)/L20<-0.25,(H20-O20)<0),IF(O20>L20,L20*K$1,K$2*O20),H20),100),"") -> 80600 | L20: 217600 | N20: =((SP+SO)/8)*(45/60) -> 32468.75 | O20: =SUM(M20:N20) -> 32468.75 | P20: =+K20/O20 -> 2.4823869 | Q20: =+K20/L20 -> 0.37040441 | R20: =+K20-O20 -> 48131.25 | T20: Dias costeados | W20: =+O13/W19 -> 0 | Y20: =+O13/Y19 -> 0
A21: 3 | B21: 7 | C21: 72102201-006 | D21: Control del estado de los sistemas del equipo: Combustible, ventilaci｢n, lubricaci｢n y arranque. | E21: unidad de medida: Unidad presentación: EVENTO | F21: 1 | G21: mínimo: 0,00 máximo: 0,00 | H21: =+IFERROR(CEILING(HLOOKUP(A21,$C$8:$K$9,2,0)*L21,100),"") -> 68500 | I21: =IFERROR(H21*1,"") -> 68500 | J21: procedencia: | K21: =IFERROR(FLOOR(IF(AND((H21-L21)/L21<-0.25,(H21-O21)<0),IF(O21>L21,L21*K$1,K$2*O21),H21),100),"") -> 68500 | L21: 185000 | N21: =((SP+SO)/8)*(20/60) -> 14430.556 | O21: =SUM(M21:N21) -> 14430.556 | P21: =+K21/O21 -> 4.746872 | Q21: =+K21/L21 -> 0.37027027 | R21: =+K21-O21 -> 54069.444 | T21: Meses costeados | W21: =+W20/26 -> 0 | Y21: =+Y20/26 -> 0
A22: 3 | B22: 8 | C22: 72102201-006 | D22: Revisiвn del estado de parаmetros mecаnicos (presiвn de aceite, temperatura, RPM) | E22: unidad de medida: Unidad presentación: EVENTO | F22: 1 | G22: mínimo: 0,00 máximo: 0,00 | H22: =+IFERROR(CEILING(HLOOKUP(A22,$C$8:$K$9,2,0)*L22,100),"") -> 70700 | I22: =IFERROR(H22*1,"") -> 70700 | J22: procedencia: | K22: =IFERROR(FLOOR(IF(AND((H22-L22)/L22<-0.25,(H22-O22)<0),IF(O22>L22,L22*K$1,K$2*O22),H22),100),"") -> 70700 | L22: 191000 | N22: =((SP+SO)/8)*(10/60) -> 7215.2778 | O22: =SUM(M22:N22) -> 7215.2778 | P22: =+K22/O22 -> 9.7986526 | Q22: =+K22/L22 -> 0.37015707 | R22: =+K22-O22 -> 63484.722
A23: 3 | B23: 9 | C23: 72102201-006 | D23: Revisiвn del estado de parаmetros elВctricos (tensiвn, frecuencia) | E23: unidad de medida: Unidad presentación: EVENTO | F23: 1 | G23: mínimo: 0,00 máximo: 0,00 | H23: =+IFERROR(CEILING(HLOOKUP(A23,$C$8:$K$9,2,0)*L23,100),"") -> 58400 | I23: =IFERROR(H23*1,"") -> 58400 | J23: procedencia: | K23: =IFERROR(FLOOR(IF(AND((H23-L23)/L23<-0.25,(H23-O23)<0),IF(O23>L23,L23*K$1,K$2*O23),H23),100),"") -> 58400 | L23: 157667 | N23: =((SP+SO)/8)*(10/60) -> 7215.2778 | O23: =SUM(M23:N23) -> 7215.2778 | P23: =+K23/O23 -> 8.0939365 | Q23: =+K23/L23 -> 0.37040091 | R23: =+K23-O23 -> 51184.722
A24: 3 | B24: 10 | C24: 72102201-006 | D24: Chequeo de funcionamiento del indicador de nivel de combustible y del indicador del filtro de aire. | E24: unidad de medida: Unidad presentación: EVENTO | F24: 1 | G24: mínimo: 0,00 máximo: 0,00 | H24: =+IFERROR(CEILING(HLOOKUP(A24,$C$8:$K$9,2,0)*L24,100),"") -> 46800 | I24: =IFERROR(H24*1,"") -> 46800 | J24: procedencia: | K24: =IFERROR(FLOOR(IF(AND((H24-L24)/L24<-0.25,(H24-O24)<0),IF(O24>L24,L24*K$1,K$2*O24),H24),100),"") -> 46800 | L24: 126333 | N24: =((SP+SO)/8)*(10/60) -> 7215.2778 | O24: =SUM(M24:N24) -> 7215.2778 | P24: =+K24/O24 -> 6.4862368 | Q24: =+K24/L24 -> 0.37044953 | R24: =+K24-O24 -> 39584.722
A25: 1 | B25: 11 | C25: 72102201-006 | D25: Chequeo de cables sueltos flojos, pelados, quemados, da兀dos, terminales flojos. | E25: unidad de medida: Unidad presentación: EVENTO | F25: 1 | G25: mínimo: 0,00 máximo: 0,00 | H25: =+IFERROR(CEILING(HLOOKUP(A25,$C$8:$K$9,2,0)*L25,100),"") -> 9100 | I25: =IFERROR(H25*1,"") -> 9100 | J25: procedencia: | K25: =IFERROR(FLOOR(IF(AND((H25-L25)/L25<-0.25,(H25-O25)<0),IF(O25>L25,M25*K$1,K$2*N25),H25),100),"") -> 5400 | L25: 129000 | N25: =((SP+SO)/8)*(15/60) -> 10822.917 | O25: =SUM(M25:N25) -> 10822.917 | P25: =+K25/O25 -> 0.49894129 | Q25: =+K25/L25 -> 0.041860465
A26: 4 | B26: 12 | C26: 72102201-006 | D26: Chequeo de protectores en mal estado o flojos, ajuste de soportes. | E26: unidad de medida: Unidad presentación: EVENTO | F26: 1 | G26: mínimo: 0,00 máximo: 0,00 | H26: =+IFERROR(CEILING(HLOOKUP(A26,$C$8:$K$9,2,0)*L26,100),"") -> 86600 | I26: =IFERROR(H26*1,"") -> 86600 | J26: procedencia: | K26: =IFERROR(FLOOR(IF(AND((H26-L26)/L26<-0.25,(H26-O26)<0),IF(O26>L26,L26*K$1,K$2*O26),H26),100),"") -> 86600 | L26: 139600 | N26: =((SP+SO)/8)*2 -> 86583.333 | O26: =SUM(M26:N26) -> 86583.333 | P26: =+K26/O26 -> 1.0001925 | Q26: =+K26/L26 -> 0.62034384 | R26: =+K26-O26 -> 16.666667
A27: 4 | B27: 13 | C27: 72102201-006 | D27: Prueba de funcionamiento de los indicadores luminosos. | E27: unidad de medida: Unidad presentación: EVENTO | F27: 1 | G27: mínimo: 0,00 máximo: 0,00 | H27: =+IFERROR(CEILING(HLOOKUP(A27,$C$8:$K$9,2,0)*L27,100),"") -> 100100 | I27: =IFERROR(H27*1,"") -> 100100 | J27: procedencia: | K27: =IFERROR(FLOOR(IF(AND((H27-L27)/L27<-0.25,(H27-O27)<0),IF(O27>L27,L27*K$1,K$2*O27),H27),100),"") -> 100100 | L27: 161333 | N27: =((SP+SO)/8)*(30/60) -> 21645.833 | O27: =SUM(M27:N27) -> 21645.833 | P27: =+K27/O27 -> 4.6244466 | Q27: =+K27/L27 -> 0.62045583 | R27: =+K27-O27 -> 78454.167
A28: 4 | B28: 14 | C28: 72102201-006 | D28: Limpieza de conectores de bater｛ | E28: unidad de medida: Unidad presentación: EVENTO | F28: 1 | G28: mínimo: 0,00 máximo: 0,00 | H28: =+IFERROR(CEILING(HLOOKUP(A28,$C$8:$K$9,2,0)*L28,100),"") -> 107500 | I28: =IFERROR(H28*1,"") -> 107500 | J28: procedencia: | K28: =IFERROR(FLOOR(IF(AND((H28-L28)/L28<-0.25,(H28-O28)<0),IF(O28>L28,L28*K$1,K$2*O28),H28),100),"") -> 107500 | L28: 173333 | N28: =((SP+SO)/8)*(15/60) -> 10822.917 | O28: =SUM(M28:N28) -> 10822.917 | P28: =+K28/O28 -> 9.9326275 | Q28: =+K28/L28 -> 0.6201935 | R28: =+K28-O28 -> 96677.083
A29: 4 | B29: 15 | C29: 72102201-006 | D29: Pruebas de motor en vac｡o y en carga. | E29: unidad de medida: Unidad presentación: EVENTO | F29: 1 | G29: mínimo: 0,00 máximo: 0,00 | H29: =+IFERROR(CEILING(HLOOKUP(A29,$C$8:$K$9,2,0)*L29,100),"") -> 170400 | I29: =IFERROR(H29*1,"") -> 170400 | J29: procedencia: | K29: =IFERROR(FLOOR(IF(AND((H29-L29)/L29<-0.25,(H29-O29)<0),IF(O29>L29,L29*K$1,K$2*O29),H29),100),"") -> 170400 | L29: 274700 | N29: =((SP+SO)/8)*(40/60) -> 28861.111 | O29: =SUM(M29:N29) -> 28861.111 | P29: =+K29/O29 -> 5.9041386 | Q29: =+K29/L29 -> 0.62031307 | R29: =+K29-O29 -> 141538.89
A30: 3 | B30: 16 | C30: 80111613-9999 | D30: Mano de obra por configuraci｢n y programaci｢n de panel de control Caterpillar. | E30: unidad de medida: Unidad presentación: EVENTO | F30: 1 | G30: mínimo: 0,00 máximo: 0,00 | H30: =+IFERROR(CEILING(HLOOKUP(A30,$C$8:$K$9,2,0)*L30,100),"") -> 88700 | I30: =IFERROR(H30*1,"") -> 88700 | J30: procedencia: | K30: =IFERROR(FLOOR(IF(AND((H30-L30)/L30<-0.25,(H30-O30)<0),IF(O30>L30,L30*K$1,K$2*O30),H30),100),"") -> 88700 | L30: 239640 | N30: =((SP+SO)/8)*(45/60) -> 32468.75 | O30: =SUM(M30:N30) -> 32468.75 | P30: =+K30/O30 -> 2.7318576 | Q30: =+K30/L30 -> 0.37013854 | R30: =+K30-O30 -> 56231.25
A31: 2 | B31: 17 | C31: 80111613-9999 | D31: Mano de obra por configuraci｢n y calibraci｢n del sensor de presi｢n de aceite. | E31: unidad de medida: Unidad presentación: EVENTO | F31: 1 | G31: mínimo: 0,00 máximo: 0,00 | H31: =+IFERROR(CEILING(HLOOKUP(A31,$C$8:$K$9,2,0)*L31,100),"") -> 76100 | I31: =IFERROR(H31*1,"") -> 76100 | J31: procedencia: | K31: =IFERROR(FLOOR(IF(AND((H31-L31)/L31<-0.25,(H31-O31)<0),IF(O31>L31,L31*K$1,K$2*O31),H31),100),"") -> 76100 | L31: 316667 | N31: =((SP+SO)/8)*(45/60) -> 32468.75 | O31: =SUM(M31:N31) -> 32468.75 | P31: =+K31/O31 -> 2.3437921 | Q31: =+K31/L31 -> 0.24031554
A32: 2 | B32: 18 | C32: 80111613-9999 | D32: Mano de obra por instalaci｢n y fijaci｢n de supresor de picos para protecci｢n de conexi｢n RS485 del panel de control. | E32: unidad de medida: Unidad presentación: EVENTO | F32: 1 | G32: mínimo: 0,00 máximo: 0,00 | H32: =+IFERROR(CEILING(HLOOKUP(A32,$C$8:$K$9,2,0)*L32,100),"") -> 53600 | I32: =IFERROR(H32*1,"") -> 53600 | J32: procedencia: | K32: =IFERROR(FLOOR(IF(AND((H32-L32)/L32<-0.25,(H32-O32)<0),IF(O32>L32,L32*K$1,K$2*O32),H32),100),"") -> 53600 | L32: 223333 | N32: =((SP+SO)/8)*(45/60) -> 32468.75 | O32: =SUM(M32:N32) -> 32468.75 | P32: =+K32/O32 -> 1.6508181 | Q32: =+K32/L32 -> 0.24000036
A33: 1 | B33: 19 | C33: 72102201-006 | D33: Inspecci｢n / ajuste de correas de alternador y ventilador | E33: unidad de medida: Unidad presentación: EVENTO | F33: 1 | G33: mínimo: 0,00 máximo: 0,00 | H33: =+IFERROR(CEILING(HLOOKUP(A33,$C$8:$K$9,2,0)*L33,100),"") -> 10800 | I33: =IFERROR(H33*1,"") -> 10800 | J33: procedencia: | K33: =IFERROR(FLOOR(IF(AND((H33-L33)/L33<-0.25,(H33-O33)<0),IF(O33>L33,L33*K$1,K$2*O33),H33),100),"") -> 10800 | L33: 153667 | N33: =((O+SO)/8)*(15/60) -> 9781.25 | O33: =SUM(M33:N33) -> 9781.25 | P33: =+K33/O33 -> 1.1041534 | Q33: =+K33/L33 -> 0.070281843
A34: 2 | B34: 20 | C34: 72102201-006 | D34: Chequeo de soporte motor | E34: unidad de medida: Unidad presentación: EVENTO | F34: 1 | G34: mínimo: 0,00 máximo: 0,00 | H34: =+IFERROR(CEILING(HLOOKUP(A34,$C$8:$K$9,2,0)*L34,100),"") -> 28000 | I34: =IFERROR(H34*1,"") -> 28000 | J34: procedencia: | K34: =IFERROR(FLOOR(IF(AND((H34-L34)/L34<-0.25,(H34-O34)<0),IF(O34>L34,L34*K$1,K$2*O34),H34),100),"") -> 28000 | L34: 116633 | N34: =((O+SO)/8)*(15/60) -> 9781.25 | O34: =SUM(M34:N34) -> 9781.25 | P34: =+K34/O34 -> 2.8626198 | Q34: =+K34/L34 -> 0.24006928
A35: 6 | B35: 21 | C35: 72102201-006 | D35: Provisi｢n de Filtro de aire CATERPILLAR 110-6326. | E35: unidad de medida: Unidad presentación: EVENTO | F35: 1 | G35: mínimo: 0,00 máximo: 0,00 | H35: =+IFERROR(CEILING(HLOOKUP(A35,$C$8:$K$9,2,0)*L35,100),"") -> 675200 | I35: =IFERROR(H35*1,"") -> 675200 | J35: procedencia: | K35: =IFERROR(FLOOR(IF(AND((H35-L35)/L35<-0.25,(H35-O35)<0),IF(O35>L35,L35*K$1,K$2*O35),H35),100),"") -> 675200 | L35: 587083 | M35: 1012950 | O35: =SUM(M35:N35) -> 1012950 | P35: =+K35/O35 -> 0.66656795 | Q35: =+K35/L35 -> 1.1500929 | R35: =+K35-O35 -> -337750
A36: 6 | B36: 22 | C36: 72102201-006 | D36: Provisi｢n de Filtro de aceite CATERPILLAR 7W 2326. | E36: unidad de medida: Unidad presentación: EVENTO | F36: 1 | G36: mínimo: 0,00 máximo: 0,00 | H36: =+IFERROR(CEILING(HLOOKUP(A36,$C$8:$K$9,2,0)*L36,100),"") -> 536100 | I36: =IFERROR(H36*1,"") -> 536100 | J36: procedencia: | K36: =IFERROR(FLOOR(IF(AND((H36-L36)/L36<-0.25,(H36-O36)<0),IF(O36>L36,L36*K$1,K$2*O36),H36),100),"") -> 536100 | L36: 466096 | M36: 791000 | O36: =SUM(M36:N36) -> 791000 | P36: =+K36/O36 -> 0.67774968 | Q36: =+K36/L36 -> 1.1501922 | R36: =+K36-O36 -> -254900
A37: 6 | B37: 23 | C37: 72102201-006 | D37: Provisi｢n de Filtro de combustible. | E37: unidad de medida: Unidad presentación: EVENTO | F37: 1 | G37: mínimo: 0,00 máximo: 0,00 | H37: =+IFERROR(CEILING(HLOOKUP(A37,$C$8:$K$9,2,0)*L37,100),"") -> 480700 | I37: =IFERROR(H37*1,"") -> 480700 | J37: procedencia: | K37: =IFERROR(FLOOR(IF(AND((H37-L37)/L37<-0.25,(H37-O37)<0),IF(O37>L37,L37*K$1,K$2*O37),H37),100),"") -> 480700 | L37: 417948 | M37: 855125 | O37: =SUM(M37:N37) -> 855125 | P37: =+K37/O37 -> 0.56214004 | Q37: =+K37/L37 -> 1.1501431 | R37: =+K37-O37 -> -374425
A38: 4 | B38: 24 | C38: 72102201-006 | D38: Provisi｢n de balde de 20 (veinte) litros de aceite lubricante CATERPILLAR 15W40. | E38: unidad de medida: Unidad presentación: EVENTO | F38: 1 | G38: mínimo: 0,00 máximo: 0,00 | H38: =+IFERROR(CEILING(HLOOKUP(A38,$C$8:$K$9,2,0)*L38,100),"") -> 746500 | I38: =IFERROR(H38*1,"") -> 746500 | J38: procedencia: | K38: =IFERROR(FLOOR(IF(AND((H38-L38)/L38<-0.25,(H38-O38)<0),IF(O38>L38,L38*K$1,K$2*O38),H38),100),"") -> 902900 | L38: 1203889 | M38: =1450000 -> 1450000 | O38: =SUM(M38:N38) -> 1450000 | P38: =+K38/O38 -> 0.62268966 | Q38: =+K38/L38 -> 0.74998609 | R38: =+K38-O38 -> -547100
A39: 4 | B39: 25 | C39: 72102201-006 | D39: Provisi｢n de balde de 20 (veinte) litros de refrigerante para radiador original. | E39: unidad de medida: Unidad presentación: EVENTO | F39: 1 | G39: mínimo: 0,00 máximo: 0,00 | H39: =+IFERROR(CEILING(HLOOKUP(A39,$C$8:$K$9,2,0)*L39,100),"") -> 3078000 | I39: =IFERROR(H39*1,"") -> 3078000 | J39: procedencia: | K39: =IFERROR(FLOOR(IF(AND((H39-L39)/L39<-0.25,(H39-O39)<0),IF(O39>L39,L39*K$1,K$2*O39),H39),100),"") -> 3078000 | L39: =4964467 -> 4964467 | M39: 1480000 | O39: =SUM(M39:N39) -> 1480000 | P39: =+K39/O39 -> 2.0797297 | Q39: =+K39/L39 -> 0.62000614 | R39: =+K39-O39 -> 1598000
A40: 2 | B40: 26 | C40: 72102201-006 | D40: Provisi｢n y cambio de bater｡a, CATERPILLAR de 12 volt, 65 Ah. | E40: unidad de medida: Unidad presentación: EVENTO | F40: 1 | G40: mínimo: 0,00 máximo: 0,00 | H40: =+IFERROR(CEILING(HLOOKUP(A40,$C$8:$K$9,2,0)*L40,100),"") -> 543100 | I40: =IFERROR(H40*1,"") -> 543100 | J40: procedencia: | K40: =IFERROR(FLOOR(IF(AND((H40-L40)/L40<-0.25,(H40-O40)<0),IF(O40>L40,L40*K$1,K$2*O40),H40),100),"") -> 550000 | L40: 2262750 | M40: 1100000 | O40: =SUM(M40:N40) -> 1100000 | P40: =+K40/O40 -> 0.5 | Q40: =+K40/L40 -> 0.24306706
A41: 13 | B41: 27 | C41: 72102201-006 | D41: Provisi｢n y cambio de panel de control Caterpillar PowerWizard 1.1, incluyendo programaci｢n. | E41: unidad de medida: Unidad presentación: EVENTO | F41: 1 | G41: mínimo: 0,00 máximo: 0,00 | H41: =+IFERROR(CEILING(HLOOKUP(A41,$C$8:$K$9,2,0)*L41,100),"") -> 333700 | I41: =IFERROR(H41*1,"") -> 333700 | J41: procedencia: | K41: =IFERROR(FLOOR(IF(AND((H41-L41)/L41<-0.25,(H41-O41)<0),IF(O41>L41,L41*K$1,K$2*O41),H41),100),"") -> 2796300 | L41: 8340667 | M41: =9321000*0.6 -> 5592600 | O41: =SUM(M41:N41) -> 5592600 | P41: =+K41/O41 -> 0.5 | Q41: =+K41/L41 -> 0.33526096
...
